mplus_output/bi-24-SHARE_W1.out
Mplus VERSION 8.1 (Mac)
MUTHEN & MUTHEN
05/27/2020  10:29 PM

INPUT INSTRUCTIONS

  DATA:
  FILE = "bi-24-SHARE_W1.dat";

  VARIABLE:
  NAMES = mplusid UDAT UDAY UMON UYER UIWR UDWR UANI URE3 URE4 URE6;
   MISSING=.;
   CATEGORICAL ARE all; idvariable = mplusid;
  ANALYSIS:
  estimator = wlsmv; coverage=0;
  MODEL:
  g by UDAT * ;
   g by UDAY * ;
   g by UMON * ;
   g by UYER * ;
   g by UIWR * ;
   g by UDWR * ;
   g by URE3 * ;
   g by URE6 * ;
   g by UANI * ;
   g by URE4 * ;
   s1 by UIWR @ 1 ;
   s1 by UDWR @ 1 ;
   g @ 1;
   s1 * ;
   g with s1 @ 0 ;

  OUTPUT:
  standardized; svalues;



*** WARNING
  Data set contains cases with missing on all variables.
  These cases were not included in the analysis.
  Number of cases with missing on all variables:  519
   1 WARNING(S) FOUND IN THE INPUT INSTRUCTIONS




SUMMARY OF ANALYSIS

Number of groups                                                 1
Number of observations                                       29932

Number of dependent variables                                   10
Number of independent variables                                  0
Number of continuous latent variables                            2

Observed dependent variables

  Binary and ordered categorical (ordinal)
   UDAT        UDAY        UMON        UYER        UIWR        UDWR
   UANI        URE3        URE4        URE6

Continuous latent variables
   G           S1

Variables with special functions

  ID variable           MPLUSID

Estimator                                                    WLSMV
Maximum number of iterations                                  1000
Convergence criterion                                    0.500D-04
Maximum number of steepest descent iterations                   20
Maximum number of iterations for H1                           2000
Convergence criterion for H1                             0.100D-03
Parameterization                                             DELTA
Link                                                        PROBIT

Input data file(s)
  bi-24-SHARE_W1.dat

Input data format  FREE


SUMMARY OF DATA

     Number of missing data patterns            46


COVARIANCE COVERAGE OF DATA

Minimum covariance coverage value   0.000


     PROPORTION OF DATA PRESENT


           Covariance Coverage
              UDAT          UDAY          UMON          UYER          UIWR
              ________      ________      ________      ________      ________
 UDAT           0.996
 UDAY           0.995         0.996
 UMON           0.995         0.996         0.996
 UYER           0.995         0.996         0.996         0.996
 UIWR           0.992         0.992         0.992         0.992         0.996
 UDWR           0.992         0.993         0.993         0.993         0.996
 UANI           0.988         0.989         0.989         0.989         0.989
 URE3           0.825         0.825         0.825         0.825         0.824
 URE4           0.661         0.661         0.661         0.661         0.660
 URE6           0.412         0.412         0.412         0.412         0.412


           Covariance Coverage
              UDWR          UANI          URE3          URE4          URE6
              ________      ________      ________      ________      ________
 UDWR           0.996
 UANI           0.989         0.990
 URE3           0.824         0.824         0.825
 URE4           0.660         0.660         0.661         0.661
 URE6           0.412         0.411         0.412         0.412         0.412


UNIVARIATE PROPORTIONS AND COUNTS FOR CATEGORICAL VARIABLES

    UDAT
      Category 1    0.127         3789.000
      Category 2    0.873        26009.000
    UDAY
      Category 1    0.029          868.000
      Category 2    0.971        28942.000
    UMON
      Category 1    0.021          616.000
      Category 2    0.979        29193.000
    UYER
      Category 1    0.023          675.000
      Category 2    0.977        29134.000
    UIWR
      Category 1    0.021          630.000
      Category 2    0.037         1102.000
      Category 3    0.051         1533.000
      Category 4    0.112         3342.000
      Category 5    0.185         5511.000
      Category 6    0.423        12599.000
      Category 7    0.111         3318.000
      Category 8    0.045         1337.000
      Category 9    0.012          357.000
      Category 10    0.003           80.000
    UDWR
      Category 1    0.102         3054.000
      Category 2    0.101         3010.000
      Category 3    0.132         3934.000
      Category 4    0.191         5708.000
      Category 5    0.192         5733.000
      Category 6    0.225         6703.000
      Category 7    0.035         1050.000
      Category 8    0.014          421.000
      Category 9    0.005          150.000
      Category 10    0.002           60.000
    UANI
      Category 1    0.006          164.000
      Category 2    0.015          432.000
      Category 3    0.064         1908.000
      Category 4    0.158         4674.000
      Category 5    0.218         6456.000
      Category 6    0.214         6354.000
      Category 7    0.164         4873.000
      Category 8    0.088         2598.000
      Category 9    0.043         1285.000
      Category 10    0.030          889.000
    URE3
      Category 1    0.069         1708.000
      Category 2    0.931        22992.000
    URE4
      Category 1    0.308         6094.000
      Category 2    0.692        13690.000
    URE6
      Category 1    0.601         7417.000
      Category 2    0.399         4922.000


     WARNING:  THE BIVARIATE TABLE OF URE4 AND URE3 HAS AN EMPTY CELL.

     WARNING:  THE BIVARIATE TABLE OF URE4 AND URE3 HAS AN EMPTY CELL.

     WARNING:  THE BIVARIATE TABLE OF URE6 AND URE3 HAS AN EMPTY CELL.

     WARNING:  THE BIVARIATE TABLE OF URE6 AND URE3 HAS AN EMPTY CELL.

     WARNING:  THE BIVARIATE TABLE OF URE6 AND URE4 HAS AN EMPTY CELL.

     WARNING:  THE BIVARIATE TABLE OF URE6 AND URE4 HAS AN EMPTY CELL.


THE MODEL ESTIMATION TERMINATED NORMALLY



MODEL FIT INFORMATION

Number of Free Parameters                       45

Chi-Square Test of Model Fit

          Value                           2168.840*
          Degrees of Freedom                    34
          P-Value                           0.0000

*   The chi-square value for MLM, MLMV, MLR, ULSMV, WLSM and WLSMV cannot be used
    for chi-square difference testing in the regular way.  MLM, MLR and WLSM
    chi-square difference testing is described on the Mplus website.  MLMV, WLSMV,
    and ULSMV difference testing is done using the DIFFTEST option.

RMSEA (Root Mean Square Error Of Approximation)

          Estimate                           0.046
          90 Percent C.I.                    0.044  0.047
          Probability RMSEA <= .05           1.000

CFI/TLI

          CFI                                0.983
          TLI                                0.978

Chi-Square Test of Model Fit for the Baseline Model

          Value                         128360.654
          Degrees of Freedom                    45
          P-Value                           0.0000

SRMR (Standardized Root Mean Square Residual)

          Value                              0.060

Optimum Function Value for Weighted Least-Squares Estimator

          Value                     0.27365794D-01



MODEL RESULTS

                                                    Two-Tailed
                    Estimate       S.E.  Est./S.E.    P-Value

 G        BY
    UDAT               0.507      0.009     58.273      0.000
    UDAY               0.683      0.012     55.601      0.000
    UMON               0.842      0.011     78.860      0.000
    UYER               0.948      0.010     95.205      0.000
    UIWR               0.697      0.005    142.068      0.000
    UDWR               0.647      0.005    126.495      0.000
    URE3               0.334      0.012     27.712      0.000
    URE6               0.197      0.010     19.100      0.000
